Workbook

Sheet Exercises
A1: Exercise #1
A2: You will have to first download the two files, ‘payroll_data.txt’ and ‘reference_data.txt’ from Canvas(Modules->Chapter 2 Data Analysis with Excel) | B2: Answers (if column A has question)
A3: Import ‘payroll_data.txt’ file into a new tab and rename it as 'Payroll Data' | B3: Done | N3: =Exercises!C14 -> 0 | O3: =Exercises!C16 -> XLOOKUP(A3,'Reference Data'!A:A,'Reference Data'!C:C)
A4: How many rows are there? | B4: 201
A5: How many columns are there? | B5: 9
A6: What is the average salary? | B6: 87965.03 | C6: AVERAGE(F3:F203)
A7: How many missing values are in each column? | B7: 86
A8: Exercise #2
A9: Address any data quality issues identified previous Exercise. | B9: Salary & overtime stored as text Inconsistent department names (Bizkits vs Biscuits) NJ division labeling issue Duplicate Employee IDs
A10: Create a new column with total compensation (salary plus overtime pay)… what is the average total compensation? | B10: 95001.906 | C10: SUBTOTAL(101,M2:M203)
A11: Add a column for the employee’s tenure at the company in years. | B11: Done | C11: YEAR(TODAY())-YEAR(H3)
A12: It turns out that all of the NJ employees work for separate division called “Tasty New Jersey”. Correct the Division column with this information. | B12: Done | C12: IF(G3="NJ","Tasty New Jersey",B3)
A13: Create a binary column (0/1) that identifies employees of the “Tasty” operating units. | B13: Done | C13: IF(LEFT(C2,5)="Tasty",1,0)
A14: Import ‘reference_data.txt’ file into a new tab and rename it as 'Reference Data' | B14: Done
A15: Add columns for Job Position and Gender in the 'Payroll Data' tab and fill them with data from the ‘Reference Data’ worksheet. | B15: Done | C15: XLOOKUP(A3,'Reference Data'!A:A,'Reference Data'!B:B) | D15: Note: Employee #574 has incorrect data; I didn't correct it.
A16: Exercise #3 | C16: XLOOKUP(A3,'Reference Data'!A:A,'Reference Data'!C:C)
A17: What is the average percentage of total compensation that is overtime pay, not including staff with no overtime pay? | B17: 0.1351 | C17: AVERAGEIF(L3:L203,">0",N3:N203)
A18: Create a pivot table with the following statistics by Operating Unit: - Number of employees - Average total compensation - Average tenure (in years) | B18: Done | C18: Rows: Job Titles Columns: Operating Units Values: Employee ID, Avg total compensation, Avg Tenure
A19: Add Job Title to the pivot table across the columns | B19: Done | D19: Note: I have problem with placing in the column for some reason, so I just put it in rows
A20: Exercise #4
A21: Create a pivot table to show Number of Employess by State | B21: Done
A22: Create a bar plot with the number of employees by State using the pivot table data from above step | B22: Done
A23: add meaningful titles for the Chart and both X and Y axes | B23: Done
A25: Append your FirstInitial and Lastname to this file and upload into Canvas under Chapter 2 Assignment 1.

Sheet Payroll Data
A1: Employee ID | B1: Division | C1: Corrected Division | D1: Operating Unit | E1: Is Tasty (0/1) | F1: Salary | G1: State | H1: Start Date | I1: Tenure (years) | J1: Division2 | K1: Dept | L1: Overtime Pay | M1: Total Compensation | N1: Overtime % | O1: Job Title | P1: Gender
A2: 138311 | B2: Tasty New York | C2: =IF(G2="NJ","Tasty New Jersey",B2) -> Tasty New Jersey | D2: Tasty Biscuits | E2: =IF(LEFT(D2,5)="Tasty",1,0) -> 1 | F2: 28334 | G2: NJ | H2: 4/18/2001 | I2: =YEAR(TODAY())-YEAR(H2) -> 25 | J2: 3350 | K2: 2000 | L2: 0 | M2: =SUM(F2,L2) -> 28334 | N2: =L2/M2 -> 0 | O2: =_xlfn.XLOOKUP(A2,'Reference Data'!A:A,'Reference Data'!B:B) -> Administrative Support | P2: =_xlfn.XLOOKUP(A2,'Reference Data'!A:A,'Reference Data'!C:C) -> F
A3: 390 | B3: Tasty New York | C3: =IF(G3="NJ","Tasty New Jersey",B3) -> Tasty New York | D3: IT Services | E3: =IF(LEFT(D3,5)="Tasty",1,0) -> 0 | F3: 56555 | G3: NY | H3: 8/20/2011 | I3: =YEAR(TODAY())-YEAR(H3) -> 15 | J3: 3810 | K3: 3000 | L3: 0 | M3: =SUM(F3,L3) -> 56555 | N3: =L3/M3 -> 0 | O3: =_xlfn.XLOOKUP(A3,'Reference Data'!A:A,'Reference Data'!B:B) -> Assistant | P3: =_xlfn.XLOOKUP(A3,'Reference Data'!A:A,'Reference Data'!C:C) -> F
A4: 138661 | B4: Tasty New York | C4: =IF(G4="NJ","Tasty New Jersey",B4) -> Tasty New Jersey | D4: Tasty Soups | E4: =IF(LEFT(D4,5)="Tasty",1,0) -> 1 | F4: 26887 | G4: NJ | H4: 6/19/2002 | I4: =YEAR(TODAY())-YEAR(H4) -> 24 | J4: 3364 | K4: 2300 | L4: 0 | M4: =SUM(F4+L4) -> 26887 | N4: =L4/M4 -> 0 | O4: =_xlfn.XLOOKUP(A4,'Reference Data'!A:A,'Reference Data'!B:B) -> Administrative Support | P4: =_xlfn.XLOOKUP(A4,'Reference Data'!A:A,'Reference Data'!C:C) -> M
A5: 138707 | B5: Tasty New York | C5: =IF(G5="NJ","Tasty New Jersey",B5) -> Tasty New Jersey | D5: Tasty Soups | E5: =IF(LEFT(D5,5)="Tasty",1,0) -> 1 | F5: 29678.42 | G5: NJ | H5: 9/11/2002 | I5: =YEAR(TODAY())-YEAR(H5) -> 24 | J5: 3364 | K5: 2500 | L5: 0 | M5: =SUM(F5+L5) -> 29678.42 | N5: =L5/M5 -> 0 | O5: =_xlfn.XLOOKUP(A5,'Reference Data'!A:A,'Reference Data'!B:B) -> Administrative Support | P5: =_xlfn.XLOOKUP(A5,'Reference Data'!A:A,'Reference Data'!C:C) -> M
A6: 548 | B6: Tasty New York | C6: =IF(G6="NJ","Tasty New Jersey",B6) -> Tasty New York | D6: IT Services | E6: =IF(LEFT(D6,5)="Tasty",1,0) -> 0 | F6: 168449 | G6: CT | H6: 1/17/1996 | I6: =YEAR(TODAY())-YEAR(H6) -> 30 | J6: 3810 | K6: 5000 | L6: 0 | M6: =SUM(F6+L6) -> 168449 | N6: =L6/M6 -> 0 | O6: =_xlfn.XLOOKUP(A6,'Reference Data'!A:A,'Reference Data'!B:B) -> Head of IT | P6: =_xlfn.XLOOKUP(A6,'Reference Data'!A:A,'Reference Data'!C:C) -> M
A7: 574 | B7: Tasty New York | C7: =IF(G7="NJ","Tasty New Jersey",B7) -> Tasty New York | D7: IT Services | E7: =IF(LEFT(D7,5)="Tasty",1,0) -> 0 | F7: 38917 | G7: NY | H7: 4/6/2005 | I7: =YEAR(TODAY())-YEAR(H7) -> 21 | J7: 3810 | K7: 4000 | L7: 0 | M7: =SUM(F7+L7) -> 38917 | N7: =L7/M7 -> 0 | O7: =_xlfn.XLOOKUP(A7,'Reference Data'!A:A,'Reference Data'!B:B) -> Assistant | P7: =_xlfn.XLOOKUP(A7,'Reference Data'!A:A,'Reference Data'!C:C) -> Administrative Support
A8: 601 | B8: Tasty New York | C8: =IF(G8="NJ","Tasty New Jersey",B8) -> Tasty New York | D8: IT Services | E8: =IF(LEFT(D8,5)="Tasty",1,0) -> 0 | F8: 79585 | G8: NY | H8: 9/1/1999 | I8: =YEAR(TODAY())-YEAR(H8) -> 27 | J8: 3810 | K8: 3000 | L8: 0 | M8: =SUM(F8+L8) -> 79585 | N8: =L8/M8 -> 0 | O8: =_xlfn.XLOOKUP(A8,'Reference Data'!A:A,'Reference Data'!B:B) -> IT Manager | P8: =_xlfn.XLOOKUP(A8,'Reference Data'!A:A,'Reference Data'!C:C) -> M
A9: 138795 | B9: Tasty New York | C9: =IF(G9="NJ","Tasty New Jersey",B9) -> Tasty New Jersey | D9: Tasty Biscuits | E9: =IF(LEFT(D9,5)="Tasty",1,0) -> 1 | F9: 25990 | G9: NJ | H9: 7/11/2011 | I9: =YEAR(TODAY())-YEAR(H9) -> 15 | J9: 3338 | K9: 2000 | L9: 0 | M9: =SUM(F9+L9) -> 25990 | N9: =L9/M9 -> 0 | O9: =_xlfn.XLOOKUP(A9,'Reference Data'!A:A,'Reference Data'!B:B) -> Administrative Support | P9: =_xlfn.XLOOKUP(A9,'Reference Data'!A:A,'Reference Data'!C:C) -> F
A10: 52250 | B10: Tasty New York | C10: =IF(G10="NJ","Tasty New Jersey",B10) -> Tasty New York | D10: Luxury Treats | E10: =IF(LEFT(D10,5)="Tasty",1,0) -> 0 | F10: 100507 | G10: CT | H10: 2/28/1951 | I10: =YEAR(TODAY())-YEAR(H10) -> 75 | J10: 3360 | K10: 5000 | L10: 2010 | M10: =SUM(F10+L10) -> 102517 | N10: =L10/M10 -> 0.019606504 | O10: =_xlfn.XLOOKUP(A10,'Reference Data'!A:A,'Reference Data'!B:B) -> Plant Supervisor | P10: =_xlfn.XLOOKUP(A10,'Reference Data'!A:A,'Reference Data'!C:C) -> M
A11: 53024 | B11: Tasty New York | C11: =IF(G11="NJ","Tasty New Jersey",B11) -> Tasty New York | D11: Luxury Treats | E11: =IF(LEFT(D11,5)="Tasty",1,0) -> 0 | F11: 193565 | G11: NY | H11: 6/28/1967 | I11: =YEAR(TODAY())-YEAR(H11) -> 59 | J11: 3360 | K11: 4000 | L11: 29035 | M11: =SUM(F11+L11) -> 222600 | N11: =L11/M11 -> 0.13043576 | O11: =_xlfn.XLOOKUP(A11,'Reference Data'!A:A,'Reference Data'!B:B) -> Plant Leader | P11: =_xlfn.XLOOKUP(A11,'Reference Data'!A:A,'Reference Data'!C:C) -> M
A12: 53725 | B12: Tasty New York | C12: =IF(G12="NJ","Tasty New Jersey",B12) -> Tasty New York | D12: Tasty Biscuits | E12: =IF(LEFT(D12,5)="Tasty",1,0) -> 1 | F12: 186310 | G12: NY | H12: 3/18/1959 | I12: =YEAR(TODAY())-YEAR(H12) -> 67 | J12: 3361 | K12: 3000 | L12: 0 | M12: =SUM(F12+L12) -> 186310 | N12: =L12/M12 -> 0 | O12: =_xlfn.XLOOKUP(A12,'Reference Data'!A:A,'Reference Data'!B:B) -> Director | P12: =_xlfn.XLOOKUP(A12,'Reference Data'!A:A,'Reference Data'!C:C) -> M
A13: 53873 | B13: Tasty New York | C13: =IF(G13="NJ","Tasty New Jersey",B13) -> Tasty New York | D13: Luxury Treats | E13: =IF(LEFT(D13,5)="Tasty",1,0) -> 0 | F13: 108307 | G13: NY | H13: 5/9/1962 | I13: =YEAR(TODAY())-YEAR(H13) -> 64 | J13: 3360 | K13: 3000 | L13: 0 | M13: =SUM(F13+L13) -> 108307 | N13: =L13/M13 -> 0 | O13: =_xlfn.XLOOKUP(A13,'Reference Data'!A:A,'Reference Data'!B:B) -> Plant Supervisor | P13: =_xlfn.XLOOKUP(A13,'Reference Data'!A:A,'Reference Data'!C:C) -> M
A14: 53725 | B14: Tasty New York | C14: =IF(G14="NJ","Tasty New Jersey",B14) -> Tasty New York | D14: Tasty Biscuits | E14: =IF(LEFT(D14,5)="Tasty",1,0) -> 1 | F14: 186310 | G14: NY | H14: 3/18/1959 | I14: =YEAR(TODAY())-YEAR(H14) -> 67 | J14: 3361 | K14: 3000 | L14: 0 | M14: =SUM(F14+L14) -> 186310 | N14: =L14/M14 -> 0 | O14: =_xlfn.XLOOKUP(A14,'Reference Data'!A:A,'Reference Data'!B:B) -> Director | P14: =_xlfn.XLOOKUP(A14,'Reference Data'!A:A,'Reference Data'!C:C) -> M
A15: 53725 | B15: Tasty New York | C15: =IF(G15="NJ","Tasty New Jersey",B15) -> Tasty New York | D15: Tasty Biscuits | E15: =IF(LEFT(D15,5)="Tasty",1,0) -> 1 | F15: 186310 | G15: NY | H15: 3/18/1959 | I15: =YEAR(TODAY())-YEAR(H15) -> 67 | J15: 3361 | K15: 3000 | L15: 0 | M15: =SUM(F15+L15) -> 186310 | N15: =L15/M15 -> 0 | O15: =_xlfn.XLOOKUP(A15,'Reference Data'!A:A,'Reference Data'!B:B) -> Director | P15: =_xlfn.XLOOKUP(A15,'Reference Data'!A:A,'Reference Data'!C:C) -> M
... A202: 147330 | B202: Tasty New York | C202: =IF(G202="NJ","Tasty New Jersey",B202) -> Tasty New York | D202: Natural Health Foods | E202: =IF(LEFT(D202,5)="Tasty",1,0) -> 0 | F202: 97390 | G202: NY | H202: 11/14/2001 | I202: =YEAR(TODAY())-YEAR(H202) -> 25 | J202: 3543 | K202: 1002 | L202: 9739 | M202: =SUM(F202+L202) -> 107129 | N202: =L202/M202 -> 0.090909091 | O202: =_xlfn.XLOOKUP(A202,'Reference Data'!A:A,'Reference Data'!B:B) -> Plant Supervisor | P202: =_xlfn.XLOOKUP(A202,'Reference Data'!A:A,'Reference Data'!C:C) -> F
E203: Total Salary: | F203: =SUM(F2:F202) -> 17680971 | L203: Total: | M203: =SUBTOTAL(109,M2:M202) -> 19095383
E204: Average Salary: | F204: =AVERAGE(F2:F202) -> 87965.03 | L204: Average: | M204: =SUBTOTAL(101,M2:M202) -> 95001.906 | N204: =AVERAGEIF(L2:L202,">0",N2:N202) -> 0.13508243

Sheet Reference Data
A1: Column1 | B1: Column2 | C1: Column3 | D1: Column4
A2: Employee ID | B2: Job Title | C2: Gender
A3: 383 | B3: IT Manager | C3: M
A4: 390 | B4: Assistant | C4: F
A5: 432 | B5: Assistant | C5: F
A6: 536 | B6: Assistant | C6: M
A7: 548 | B7: Head of IT | C7: M
A8: 574 | B8: Assistant | C8: Administrative Support | D8: M
A9: 601 | B9: IT Manager | C9: M
A10: 648 | B10: IT Leader | C10: F
A11: 52250 | B11: Plant Supervisor | C11: M
A12: 53024 | B12: Plant Leader | C12: M
A13: 53725 | B13: Director | C13: M
A14: 53873 | B14: Plant Supervisor | C14: M
A15: 53921 | B15: Plant Manager | C15: M
A16: 54133 | B16: Plant Supervisor | C16: F
A17: 61908 | B17: Plant Worker | C17: M
A18: 63032 | B18: Plant Manager | C18: M
A19: 63630 | B19: Plant Worker | C19: M
A20: 78018 | B20: Director | C20: M
... A200: 147366 | B200: Director | C200: F

Sheet Pivot table 1
C1: Operating Unit
A2: Job Title | B2: Values | C2: Communication & Strategic Sales | D2: Finance | E2: Human Resources | F2: IT Services | G2: Luxury Treats | H2: Marketing | I2: Natural Health Foods | J2: Plant Support Services | K2: Tasty Biscuits | L2: Tasty Bizkits | M2: Tasty Snacks Food | N2: Tasty Soups | O2: (blank) | P2: Grand Total
A3: Administrative Support | B3: Count of Employee ID | G3: 6 | I3: 5 | K3: 10 | M3: 1 | N3: 7 | P3: 29
B4: Average of Total Compensation | G4: 28843 | I4: 41178 | K4: 26455.32 | M4: 20193 | N4: 25006.939 | P4: 28922.164
B5: Average of Tenure (years) | G5: 29.666667 | I5: 44 | K5: 21.3 | M5: 29 | N5: 23.428571 | P5: 27.724138
A6: Assistant | B6: Count of Employee ID | D6: 1 | F6: 4 | J6: 2 | P6: 7
B7: Average of Total Compensation | D7: 39780 | F7: 44857 | J7: 46249 | P7: 44529.429
B8: Average of Tenure (years) | D8: 25 | F8: 20.25 | J8: 31 | P8: 24
A9: CEO | B9: Count of Employee ID | I9: 1 | P9: 1
B10: Average of Total Compensation | I10: 241749 | P10: 241749
B11: Average of Tenure (years) | I11: 15 | P11: 15
A12: Director | B12: Count of Employee ID | G12: 3 | I12: 3 | K12: 4 | M12: 2 | N12: 2 | P12: 14
B13: Average of Total Compensation | G13: 243933.33 | I13: 267407.43 | K13: 177479 | M13: 460582 | N13: 171060.5 | P13: 250515.95
B14: Average of Tenure (years) | G14: 44.666667 | I14: 24.666667 | K14: 59.75 | M14: 20 | N14: 33.5 | P14: 39.571429
A15: Finance Manager | B15: Count of Employee ID | D15: 1 | P15: 1
B16: Average of Total Compensation | D16: 100272 | P16: 100272
B17: Average of Tenure (years) | D17: 27 | P17: 27
A18: Head of Finance | B18: Count of Employee ID | D18: 1 | P18: 1
B19: Average of Total Compensation | D19: 173317 | P19: 173317
B20: Average of Tenure (years) | D20: 31 | P20: 31
A21: Head of IT | B21: Count of Employee ID | F21: 1 | P21: 1
B22: Average of Total Compensation | F22: 168449 | P22: 168449
B23: Average of Tenure (years) | F23: 30 | P23: 30
A24: Head of Marketing | B24: Count of Employee ID | H24: 1 | P24: 1
B25: Average of Total Compensation | H25: 137842 | P25: 137842
B26: Average of Tenure (years) | H26: 68 | P26: 68
A27: Head of Support Services | B27: Count of Employee ID | J27: 1 | P27: 1
B28: Average of Total Compensation | J28: 175052 | P28: 175052
B29: Average of Tenure (years) | J29: 43 | P29: 43
A30: Human Resource Officer | B30: Count of Employee ID | E30: 1 | P30: 1
B31: Average of Total Compensation | E31: 80350 | P31: 80350
B32: Average of Tenure (years) | E32: 22 | P32: 22
A33: IT Leader | B33: Count of Employee ID | F33: 3 | P33: 3
B34: Average of Total Compensation | F34: 123688.67 | P34: 123688.67
B35: Average of Tenure (years) | F35: 32.333333 | P35: 32.333333
A36: IT Manager | B36: Count of Employee ID | F36: 3 | P36: 3
B37: Average of Total Compensation | F37: 81351.667 | P37: 81351.667
B38: Average of Tenure (years) | F38: 22.666667 | P38: 22.666667
A39: Manager | B39: Count of Employee ID | J39: 2 | P39: 2
B40: Average of Total Compensation | J40: 115101 | P40: 115101
...

Sheet Pivot table 2
A2: State | B2: Count of Employee ID
A3: CT | B3: 41
A4: NJ | B4: 84
A5: NT | B5: 1
A6: NY | B6: 56
A7: WA | B7: 19
A8: (blank)
A9: Grand Total | B9: 201
